<?xml version="1.0"?>
<!-- =================================================================================== -->
<!-- |    This document was autogenerated by xacro from urdf/iiwa14_polytope_collision.urdf.xacro | -->
<!-- |    EDITING THIS FILE BY HAND IS NOT RECOMMENDED                                 | -->
<!-- =================================================================================== -->
<!-- ===================================================================== -->
<!-- Collision models: complex meshes can drastically affect run time.
     Therefore most collision models are omitted in this model and link 7 uses a
     polytope model.
-->
<!-- ===================================================================== -->
<robot xmlns:drake="http://drake.mit.edu" xmlns:xacro="http://www.ros.org/wiki/xacro" name="iiwa">
  <!-- Import Rviz colors -->
  <material name="Black">
    <color rgba="0.0 0.0 0.0 1.0"/>
  </material>
  <material name="Blue">
    <color rgba="0.0 0.0 0.8 1.0"/>
  </material>
  <material name="Green">
    <color rgba="0.0 0.8 0.0 1.0"/>
  </material>
  <material name="Grey">
    <color rgba="0.4 0.4 0.4 1.0"/>
  </material>
  <material name="Silver">
    <color rgba="0.6 0.6 0.6 1.0"/>
  </material>
  <material name="Orange">
    <color rgba="1.0 0.423529411765 0.0392156862745 1.0"/>
  </material>
  <material name="Brown">
    <color rgba="0.870588235294 0.811764705882 0.764705882353 1.0"/>
  </material>
  <material name="Red">
    <color rgba="0.8 0.0 0.0 1.0"/>
  </material>
  <material name="White">
    <color rgba="1.0 1.0 1.0 1.0"/>
  </material>
  <!-- Defines a base link that will serve as the model's root. -->
  <link name="base"/>
  <!--joint between {parent} and link_0-->
  <joint name="iiwa_base_joint" type="fixed">
    <origin rpy="0 0 0" xyz="0 0 0"/>
    <parent link="base"/>
    <child link="iiwa_link_0"/>
  </joint>
  <link name="iiwa_link_0">
    <inertial>
      <origin rpy="0 0 0" xyz="-0.001864 0.0 0.077517"/>
      <mass value="8.146413"/>
      <inertia ixx="0.044604" ixy="0.0" ixz="-0.000788" iyy="0.045465" iyz="0.0" izz="0.061904"/>
    </inertial>
    <visual>
      <origin rpy="0 0 0" xyz="0 0 0"/>
      <geometry>
        <mesh filename="./lbr_description/meshes/med14/visual/link_0.dae"/>
      </geometry>
    </visual>
    <self_collision_checking>
      <origin rpy="0 0 0" xyz="0 0 0"/>
      <geometry>
        <capsule length="0.25" radius="0.15"/>
      </geometry>
    </self_collision_checking>
  </link>
  <!-- joint between link_0 and link_1 -->
  <joint name="iiwa_joint_1" type="revolute">
    <parent link="iiwa_link_0"/>
    <child link="iiwa_link_1"/>
    <origin rpy="0 0 0" xyz="0 0 0.1575"/>
    <axis xyz="0 0 1"/>
    <limit drake:acceleration="8.57" effort="200" lower="-2.9670597283903604" upper="2.9670597283903604" velocity="1.4835298641951802"/>
    <dynamics damping="0.5"/>
  </joint>
  <link name="iiwa_link_1">
    <inertial>
      <origin rpy="0 0 0" xyz="0.0 -0.033795  0.132404"/>
      <mass value="5.591419"/>
      <inertia ixx="0.044885" ixy="0.0" ixz="0.0" iyy="0.045283" iyz="0.006703" izz="0.016776"/>
    </inertial>
    <visual>
      <origin rpy="0 0 0" xyz="0.0 0.0 -0.147"/>
      <geometry>
        <mesh filename="./lbr_description/meshes/med14/visual/link_1.dae"/>
      </geometry>
    </visual>
  </link>
  <!-- joint between link_1 and link_2 -->
  <joint name="iiwa_joint_2" type="revolute">
    <parent link="iiwa_link_1"/>
    <child link="iiwa_link_2"/>
    <origin rpy="0 0 0" xyz="0.0 -0.01 0.2125"/>
    <axis xyz="0.0 1.0 0.0"/>
    <limit drake:acceleration="8.57" effort="200" lower="-2.0943951023931953" upper="2.0943951023931953" velocity="1.4835298641951802"/>
    <dynamics damping="0.5"/>
  </joint>
  <link name="iiwa_link_2">
    <inertial>
      <origin rpy="0 0 0" xyz="0.000136 0.047546 0.076324"/>
      <mass value="6.013411"/>
      <!-- 3.95 kuka CAD value-->
      <!--4 Original Drake URDF value-->
      <inertia ixx="0.05833" ixy="-3.5e-05" ixz="5.9e-05" iyy="0.057062" iyz="0.010605" izz="0.017466"/>
    </inertial>
    <visual>
      <origin rpy="0 0 0" xyz="0.0 0.01 -0.3595"/>
      <geometry>
        <mesh filename="./lbr_description/meshes/med14/visual/link_2.dae"/>
      </geometry>
    </visual>
  </link>
  <!-- joint between link_2 and link_3 -->
  <joint name="iiwa_joint_3" type="revolute">
    <parent link="iiwa_link_2"/>
    <child link="iiwa_link_3"/>
    <origin rpy="0 0 0" xyz="0.0 0.01 0.228"/>
    <axis xyz="0.0 0.0 1.0"/>
    <limit drake:acceleration="8.74" effort="200" lower="-2.9670597283903604" upper="2.9670597283903604" velocity="1.7453292519943295"/>
    <dynamics damping="0.5"/>
  </joint>
  <link name="iiwa_link_3">
    <inertial>
      <origin rpy="0 0 0" xyz="0.0 0.034913 0.123108"/>
      <mass value="3.65879"/>
      <!--3.18 kuka CAD value-->
      <!--3 Original Drake URDF value-->
      <inertia ixx="0.02296" ixy="0.0" ixz="0.0" iyy="0.021913" iyz="-0.004065" izz="0.00814"/>
    </inertial>
    <visual>
      <origin rpy="0 0 0" xyz="0.0 0.0 -0.5875"/>
      <geometry>
        <mesh filename="./lbr_description/meshes/med14/visual/link_3.dae"/>
      </geometry>
    </visual>
  </link>
  <!-- joint between link_3 and link_4 -->
  <joint name="iiwa_joint_4" type="revolute">
    <parent link="iiwa_link_3"/>
    <child link="iiwa_link_4"/>
    <origin rpy="0 0 0" xyz="0.0 0.0105 0.192"/>
    <axis xyz="0.0 -1.0 0.0"/>
    <limit drake:acceleration="11.36" effort="200" lower="-2.0943951023931953" upper="2.0943951023931953" velocity="1.3089969389957472"/>
    <dynamics damping="0.5"/>
  </joint>
  <link name="iiwa_link_4">
    <inertial>
      <origin rpy="0 0 0" xyz="0.0 -0.039793  0.086944"/>
      <mass value="4.358267"/>
      <!--2.74 kuka CAD value-->
      <!--2.7 Original Drake URDF value-->
      <inertia ixx="0.034255" ixy="0.0" ixz="0.0" iyy="0.032512" iyz="-0.006365" izz="0.010444"/>
    </inertial>
    <visual>
      <origin rpy="0 0 0" xyz="0.0 -0.0105 -0.7795"/>
      <geometry>
        <mesh filename="./lbr_description/meshes/med14/visual/link_4.dae"/>
      </geometry>
    </visual>
  </link>
  <!-- joint between link_4 and link_5 -->
  <joint name="iiwa_joint_5" type="revolute">
    <parent link="iiwa_link_4"/>
    <child link="iiwa_link_5"/>
    <origin rpy="0 0 0" xyz="0.0 -0.0105 0.2075"/>
    <axis xyz="0.0 0.0 1.0"/>
    <limit drake:acceleration="12.23" effort="200" lower="-2.9670597283903604" upper="2.9670597283903604" velocity="2.2689280275926285"/>
    <dynamics damping="0.5"/>
  </joint>
  <link name="iiwa_link_5">
    <inertial>
      <origin rpy="0 0 0" xyz="0.0 -0.029824  0.076267"/>
      <mass value="1.653015"/>
      <!--1.69 kuka CAD value-->
      <!--1.7 Original Drake URDF value-->
      <inertia ixx="0.009172" ixy="0.0" ixz="0.0" iyy="0.007714" iyz="0.003033" izz="0.004159"/>
    </inertial>
    <visual>
      <origin rpy="0 0 0" xyz="0.0 0.0 -0.987"/>
      <geometry>
        <mesh filename="./lbr_description/meshes/med14/visual/link_5.dae"/>
      </geometry>
    </visual>
  </link>
  <!-- joint between link_5 and link_6 -->
  <joint name="iiwa_joint_6" type="revolute">
    <parent link="iiwa_link_5"/>
    <child link="iiwa_link_6"/>
    <origin rpy="0 0 0" xyz="0.0 -0.0707 0.1925"/>
    <axis xyz="0.0 1.0 0.0"/>
    <limit drake:acceleration="15.72" effort="200" lower="-2.0943951023931953" upper="2.0943951023931953" velocity="2.356194490192345"/>
    <dynamics damping="0.5"/>
  </joint>
  <link name="iiwa_link_6">
    <inertial>
      <origin rpy="0 0 0" xyz="-1.000e-06 7.102e-02 4.953e-03"/>
      <mass value="2.598211"/>
      <!--1.8 kuka CAD value-->
      <!--1.8 Original Drake URDF value-->
      <inertia ixx="0.00764" ixy="0.0" ixz="0.0" iyy="0.007355" iyz="0.000336" izz="0.005004"/>
    </inertial>
    <visual>
      <origin rpy="0 0 0" xyz="0.0 0.0707 -1.1795"/>
      <geometry>
        <mesh filename="./lbr_description/meshes/med14/visual/link_6.dae"/>
      </geometry>
    </visual>
  </link>
  <!-- joint between link_6 and link_7 -->
  <joint name="iiwa_joint_7" type="revolute">
    <parent link="iiwa_link_6"/>
    <child link="iiwa_link_7"/>
    <origin rpy="0 0 0" xyz="0.0 0.0707 0.091"/>
    <axis xyz="0.0 0.0 1.0"/>
    <limit drake:acceleration="15.72" effort="200" lower="-3.0543261909900763" upper="3.0543261909900763" velocity="2.356194490192345"/>
    <dynamics damping="0.5"/>
  </joint>
  <link name="iiwa_link_7">
    <inertial>
      <origin rpy="0 0 0" xyz="3.0000e-06 -2.0000e-06 1.3782e-02"/>
      <mass value="0.280474"/>
      <!--0.31 kuka CAD value-->
      <!--0.3 Original Drake URDF value-->
      <inertia ixx="0.000185" ixy="0.0" ixz="0.0" iyy="0.000185" iyz="0.0" izz="0.000323"/>
    </inertial>
    <visual>
      <origin rpy="0 0 0" xyz="0.0 0.0 -1.2705"/>
      <geometry>
        <mesh filename="./lbr_description/meshes/med14/visual/link_7.dae"/>
      </geometry>
    </visual>
    <collision>
      <origin rpy="0 0 0" xyz="0.0 0.0 -1.2705"/>
      <geometry>
        <mesh filename="./lbr_description/meshes/med14/collision/link_7.obj"/>
      </geometry>
    </collision>
  </link>
  <joint name="iiwa_joint_ee" type="fixed">
    <parent link="iiwa_link_7"/>
    <child link="iiwa_link_ee_kuka"/>
    <origin rpy="3.141592653589793 3.141592653589793 3.141592653589793" xyz="0 0 0.0775"/>
    <axis xyz="0 0 1"/>
  </joint>
  <link name="iiwa_link_ee_kuka">
    </link>
  <joint name="tool0_joint" type="fixed">
    <parent link="iiwa_link_7"/>
    <child link="iiwa_link_ee"/>
    <origin rpy="0 -1.570796326794897 0" xyz="0 0 0.0775"/>
  </joint>
  <link name="iiwa_link_ee">
    </link>
  <frame link="iiwa_link_ee" name="iiwa_frame_ee" rpy="3.141592653589793 0 1.570796326794897" xyz="0.09 0 0"/>
  <drake:collision_filter_group name="iiwa_wrist">
    <drake:member link="iiwa_link_5"/>
    <drake:member link="iiwa_link_6"/>
    <drake:member link="iiwa_link_7"/>
    <drake:ignored_collision_filter_group name="iiwa_wrist"/>
  </drake:collision_filter_group>
  <!-- Load Gazebo lib and set the robot namespace -->
  <gazebo>
    <plugin filename="libgazebo_ros_control.so" name="gazebo_ros_controller">
      <robotNamespace>/iiwa</robotNamespace>
    </plugin>
  </gazebo>
  <!-- Link0 -->
  <gazebo reference="iiwa_link_0">
    <material>Gazebo/Grey</material>
    <mu1>0.2</mu1>
    <mu2>0.2</mu2>
  </gazebo>
  <!-- Link1 -->
  <gazebo reference="iiwa_link_1">
    <material>Gazebo/Orange</material>
    <mu1>0.2</mu1>
    <mu2>0.2</mu2>
  </gazebo>
  <!-- Link2 -->
  <gazebo reference="iiwa_link_2">
    <material>Gazebo/Orange</material>
    <mu1>0.2</mu1>
    <mu2>0.2</mu2>
  </gazebo>
  <!-- Link3 -->
  <gazebo reference="iiwa_link_3">
    <material>Gazebo/Orange</material>
    <mu1>0.2</mu1>
    <mu2>0.2</mu2>
  </gazebo>
  <!-- Link4 -->
  <gazebo reference="iiwa_link_4">
    <material>Gazebo/Orange</material>
    <mu1>0.2</mu1>
    <mu2>0.2</mu2>
  </gazebo>
  <!-- Link5 -->
  <gazebo reference="iiwa_link_5">
    <material>Gazebo/Orange</material>
    <mu1>0.2</mu1>
    <mu2>0.2</mu2>
  </gazebo>
  <!-- Link6 -->
  <gazebo reference="iiwa_link_6">
    <material>Gazebo/Orange</material>
    <mu1>0.2</mu1>
    <mu2>0.2</mu2>
  </gazebo>
  <!-- Link7 -->
  <gazebo reference="iiwa_link_7">
    <material>Gazebo/Grey</material>
    <mu1>0.2</mu1>
    <mu2>0.2</mu2>
  </gazebo>
  <transmission name="iiwa_tran_1">
    <robotNamespace>/iiwa</robotNamespace>
    <type>transmission_interface/SimpleTransmission</type>
    <joint name="iiwa_joint_1">
      <hardwareInterface>PositionJointInterface</hardwareInterface>
    </joint>
    <actuator name="iiwa_motor_1">
      <hardwareInterface>PositionJointInterface</hardwareInterface>
      <mechanicalReduction>1</mechanicalReduction>
      <drake:gear_ratio value="160.0" />
      <drake:rotor_inertia value="0.0001321" />
    </actuator>
  </transmission>
  <transmission name="iiwa_tran_2">
    <robotNamespace>/iiwa</robotNamespace>
    <type>transmission_interface/SimpleTransmission</type>
    <joint name="iiwa_joint_2">
      <hardwareInterface>PositionJointInterface</hardwareInterface>
    </joint>
    <actuator name="iiwa_motor_2">
      <hardwareInterface>PositionJointInterface</hardwareInterface>
      <mechanicalReduction>1</mechanicalReduction>
      <drake:gear_ratio value="160.0" />
      <drake:rotor_inertia value="0.0001321" />
    </actuator>
  </transmission>
  <transmission name="iiwa_tran_3">
    <robotNamespace>/iiwa</robotNamespace>
    <type>transmission_interface/SimpleTransmission</type>
    <joint name="iiwa_joint_3">
      <hardwareInterface>PositionJointInterface</hardwareInterface>
    </joint>
    <actuator name="iiwa_motor_3">
      <hardwareInterface>PositionJointInterface</hardwareInterface>
      <mechanicalReduction>1</mechanicalReduction>
      <drake:gear_ratio value="160.0" />
      <drake:rotor_inertia value="0.0001321" />
    </actuator>
  </transmission>
  <transmission name="iiwa_tran_4">
    <robotNamespace>/iiwa</robotNamespace>
    <type>transmission_interface/SimpleTransmission</type>
    <joint name="iiwa_joint_4">
      <hardwareInterface>PositionJointInterface</hardwareInterface>
    </joint>
    <actuator name="iiwa_motor_4">
      <hardwareInterface>PositionJointInterface</hardwareInterface>
      <mechanicalReduction>1</mechanicalReduction>
      <drake:gear_ratio value="160.0" />
      <drake:rotor_inertia value="0.0001321" />
    </actuator>
  </transmission>
  <transmission name="iiwa_tran_5">
    <robotNamespace>/iiwa</robotNamespace>
    <type>transmission_interface/SimpleTransmission</type>
    <joint name="iiwa_joint_5">
      <hardwareInterface>PositionJointInterface</hardwareInterface>
    </joint>
    <actuator name="iiwa_motor_5">
      <hardwareInterface>PositionJointInterface</hardwareInterface>
      <mechanicalReduction>1</mechanicalReduction>
      <drake:gear_ratio value="100.0" />
      <drake:rotor_inertia value="0.0001321" />
    </actuator>
  </transmission>
  <transmission name="iiwa_tran_6">
    <robotNamespace>/iiwa</robotNamespace>
    <type>transmission_interface/SimpleTransmission</type>
    <joint name="iiwa_joint_6">
      <hardwareInterface>PositionJointInterface</hardwareInterface>
    </joint>
    <actuator name="iiwa_motor_6">
      <hardwareInterface>PositionJointInterface</hardwareInterface>
      <mechanicalReduction>1</mechanicalReduction>
      <drake:gear_ratio value="160.0" />
      <drake:rotor_inertia value="0.0000454" />
    </actuator>
  </transmission>
  <transmission name="iiwa_tran_7">
    <robotNamespace>/iiwa</robotNamespace>
    <type>transmission_interface/SimpleTransmission</type>
    <joint name="iiwa_joint_7">
      <hardwareInterface>PositionJointInterface</hardwareInterface>
    </joint>
    <actuator name="iiwa_motor_7">
      <hardwareInterface>PositionJointInterface</hardwareInterface>
      <mechanicalReduction>1</mechanicalReduction>
      <drake:gear_ratio value="160.0" />
      <drake:rotor_inertia value="0.0000454" />
    </actuator>
  </transmission>
</robot>